Traceback (most recent call last):
  File "/home/runner/micromamba/envs/data-forums/lib/python3.10/site-packages/jupyter_core/utils/__init__.py", line 154, in wrapped
    asyncio.get_running_loop()
RuntimeError: no running event loop

During handling of the above exception, another exception occurred:

Traceback (most recent call last):
  File "/home/runner/micromamba/envs/data-forums/lib/python3.10/site-packages/jupyter_cache/executors/utils.py", line 58, in single_nb_execution
    executenb(
  File "/home/runner/micromamba/envs/data-forums/lib/python3.10/site-packages/nbclient/client.py", line 1319, in execute
    return NotebookClient(nb=nb, resources=resources, km=km, **kwargs).execute()
  File "/home/runner/micromamba/envs/data-forums/lib/python3.10/site-packages/jupyter_core/utils/__init__.py", line 158, in wrapped
    return loop.run_until_complete(inner)
  File "/home/runner/micromamba/envs/data-forums/lib/python3.10/asyncio/base_events.py", line 649, in run_until_complete
    return future.result()
  File "/home/runner/micromamba/envs/data-forums/lib/python3.10/site-packages/nbclient/client.py", line 709, in async_execute
    await self.async_execute_cell(
  File "/home/runner/micromamba/envs/data-forums/lib/python3.10/site-packages/nbclient/client.py", line 1062, in async_execute_cell
    await self._check_raise_for_error(cell, cell_index, exec_reply)
  File "/home/runner/micromamba/envs/data-forums/lib/python3.10/site-packages/nbclient/client.py", line 918, in _check_raise_for_error
    raise CellExecutionError.from_cell_and_msg(cell, exec_reply_content)
nbclient.exceptions.CellExecutionError: An error occurred while executing the following cell:
------------------
'''python

# Make sure begin_date is in datetime format
df_18['begin_date'] = pd.to_datetime(df_18['begin_date'])

# New column to store list of WWA names
df_18['wwa_names'] = None

# Loop through each respondent
for idx, row in tqdm(df_18.iterrows(), total=len(df_18)):
    lat = row['lat']
    lon = row['lon']
    end_date = row['begin_date']
    start_date = end_date - timedelta(days=3)

    # Build API URL with small buffer
    url = (
        f"https://mesonet.agron.iastate.edu/json/vtec_events_bypoint.py"
        f"?lat={lat}&lon={lon}"
        f"&sdate={start_date.strftime('%Y-%m-%d')}&edate={end_date.strftime('%Y-%m-%d')}"
        f"&buffer=0.1"
    )

    try:
        response = requests.get(url)
        if response.status_code == 200:
            data = response.json()
            names = [event['name'] for event in data.get('events', [])]
            df_18.at[idx, 'wwa_names'] = names
        else:
            df_18.at[idx, 'wwa_names'] = []
    except Exception as e:
        print(f"Failed for idx={idx}, lat={lat}, lon={lon}: {e}")
        df_18.at[idx, 'wwa_names'] = []

------------------


[0;36m  Cell [0;32mIn[15], line 1[0;36m[0m
[0;31m    '''python[0m
[0m    ^[0m
[0;31mSyntaxError[0m[0;31m:[0m incomplete input


